Workbook
Name Akaryakıt_Hacim_Ölçek_Kapları: Veriler!$C$28:$C$29
Name Akaryakıt_LPG_Adblue_Dispenserleri: Veriler!$C$2:$C$7
Name Aks_Kantarları: Veriler!$C$31:$C$33
Name CNG_Dispenserleri: Veriler!$C$39:$C$40
Name Demiryolu_Yük_ve_Sarnıçlı_Vagonları: Veriler!$C$35
Name Hız_İhlal_Tespit_Donanımları: Veriler!$C$42:$C$45
Name Kütle_Ölçüleri: Veriler!$C$47:$C$53
Name Lastik_Hava_Basınçölçerler: Veriler!$C$37
Name Su_Dışındaki_Sıvılar_İçin_Ölçme_Sistemleri: Veriler!$C$19:$C$26
Name Tanker_Sayaçları: Veriler!$C$16:$C$17
Name Tartı_Aletleri: Veriler!$C$9:$C$14

Sheet Fatura Detay Formu
A1: FATURA DETAYI
A2: EVRAK NO
A3: BAŞVURU (EVRAK) YILI | C3: 2026
A4: TALEP YAPAN FİRMA
A5: TAMİR AYAR FİRMASI (Fatura Tas’a Kesilecekse Doldurunuz.)
A6: FATURA ADRESİ
A7: TELEFON
A8: E-POSTA
A9: VERGİ DAİRESİ - VERGİ NO
B10: ÖLÇÜ ALETİ ADI | C10: ÖLÇÜ ALETİ BİLGİSİ | E10: FATURAYA ESAS MUAYENE ÜCRETİ (KDV HARİÇ)* | H10: ARA TOPLAM (KDV HARİÇ)
E11: ADET | F11: BİRİM FİYAT
A12: 1 | B12: Akaryakıt_LPG_Adblue_Dispenserleri | C12: Mak. Akış Hızı 130 L/dk-100 kg/dk Kadar-(Periyodik, Stok) | E12: 1 | F12: =IF($C$3="","",IFERROR(VLOOKUP(C12,Veriler!$C$2:$E$53,IF($C$3=Veriler!$A$2,2,3),0),"")) -> 904 | G12: TL | H12: =IF(OR(E12="",F12=""),"",E12*F12) -> 904 | I12: TL
A13: 2 | E13: 1 | F13: =IF($C$3="","",IFERROR(VLOOKUP(C13,Veriler!$C$2:$E$53,IF($C$3=Veriler!$A$2,2,3),0),"")) | G13: TL | H13: =IF(OR(E13="",F13=""),"",E13*F13) | I13: TL
A14: 3 | E14: 1 | F14: =IF($C$3="","",IFERROR(VLOOKUP(C14,Veriler!$C$2:$E$53,IF($C$3=Veriler!$A$2,2,3),0),"")) | G14: TL | H14: =IF(OR(E14="",F14=""),"",E14*F14) | I14: TL
A15: 4 | E15: 1 | F15: =IF($C$3="","",IFERROR(VLOOKUP(C15,Veriler!$C$2:$E$53,IF($C$3=Veriler!$A$2,2,3),0),"")) | G15: TL | H15: =IF(OR(E15="",F15=""),"",E15*F15) | I15: TL
A16: 5 | E16: 1 | F16: =IF($C$3="","",IFERROR(VLOOKUP(C16,Veriler!$C$2:$E$53,IF($C$3=Veriler!$A$2,2,3),0),"")) | G16: TL | H16: =IF(OR(E16="",F16=""),"",E16*F16) | I16: TL
A17: 6 | E17: 1 | F17: =IF($C$3="","",IFERROR(VLOOKUP(C17,Veriler!$C$2:$E$53,IF($C$3=Veriler!$A$2,2,3),0),"")) | G17: TL | H17: =IF(OR(E17="",F17=""),"",E17*F17) | I17: TL
A18: 7 | E18: 1 | F18: =IF($C$3="","",IFERROR(VLOOKUP(C18,Veriler!$C$2:$E$53,IF($C$3=Veriler!$A$2,2,3),0),"")) | G18: TL | H18: =IF(OR(E18="",F18=""),"",E18*F18) | I18: TL
A19: 8 | E19: 1 | F19: =IF($C$3="","",IFERROR(VLOOKUP(C19,Veriler!$C$2:$E$53,IF($C$3=Veriler!$A$2,2,3),0),"")) | G19: TL | H19: =IF(OR(E19="",F19=""),"",E19*F19) | I19: TL
A20: =CONCATENATE("* Bu formda yer alan muayene ücretleri ",IF(C3="","...",C3)," yılında yapılan muayene başvuruları için geçerlidir. Lütfen başvuru yılının doğruluğundan emin olunuz.") -> * Bu formda yer alan muayene ücretleri 2026 yılında yapılan muayene başvuruları için geçerlidir. Lütfen başvuru yılının doğruluğundan emin olunuz. | E20: TOPLAM (KDV HARİÇ) | H20: =IF(F12="","",SUM(H12:H19)) -> 904 | I20: TL
E21: KDV (%20) | H21: =IF(H20="","",H20*0.2) -> 180.8 | I21: TL
E22: GENEL TOPLAM (KDV DÂHİL) | H22: =IF(H20="","",H20+H21) -> 1084.8 | I22: TL
A23: DÜZENLEME TARİHİ | D23: 46222
A24: DÜZENLEYEN | D24: ADI VE SOYADI | G24: İMZA
A25: MUAYENE UZMANI | D25: Ömer Faruk MURAT

Sheet Veriler
A1: Başvuru Tarihi | B1: Ölçü Aleti Adı | C1: Ölçü Aleti Bilgisi | D1: 2025 Ücret | E1: 2026 Ücret | G1: Ölçü Aletleri
A2: 2025 | B2: Akaryakıt/LPG/Adblue Dispenserleri | C2: Mak. Akış Hızı 130 L/dk-100 kg/dk Kadar-(Periyodik, Stok) | D2: 720 | E2: 904 | F2: =(E2-D2)/D2 -> 0.25555556 | G2: Akaryakıt_LPG_Adblue_Dispenserleri
A3: 2026 | C3: Mak. Akış Hızı 130 L/dk-100 kg/dk Kadar-(TAS) | D3: 1080 | E3: 1356 | F3: =(E3-D3)/D3 -> 0.25555556 | G3: Tartı_Aletleri
C4: Mak. Akış Hızı 750 L/dk -550 kg/dk Kadar-(Periyodik, Stok) | D4: 1080 | E4: 1356 | F4: =(E4-D4)/D4 -> 0.25555556 | G4: Tanker_Sayaçları
C5: Mak. Akış Hızı 750 L/dk-550 kg/dk Kadar-(TAS) | D5: 1620 | E5: 2034 | F5: =(E5-D5)/D5 -> 0.25555556 | G5: Kütle_Ölçüleri
C6: Mak. Akış Hızı 751 L/dk 551 kg/dk Üzeri-(Periyodik, Stok) | D6: 1541 | E6: 1934 | F6: =(E6-D6)/D6 -> 0.2550292 | G6: Lastik_Hava_Basınçölçerler
C7: Mak. Akış Hızı 751 L/dk 551 kg/dk Üzeri-(TAS) | D7: 2311.5 | E7: 2901 | F7: =(E7-D7)/D7 -> 0.2550292 | G7: Akaryakıt_Hacim_Ölçek_Kapları
G8: Aks_Kantarları
B9: Tartı Aletleri | C9: Mak. Kap. 2.000-30.000 kg Arası-(Periyodik, Stok) | D9: 7197 | E9: 9032 | F9: =(E9-D9)/D9 -> 0.25496735 | G9: Demiryolu_Yük_ve_Sarnıçlı_Vagonları
A10: Düzenleme Tarihi | C10: Mak. Kap. 2.000-30.000 kg Arası-(TAS) | D10: 10795.5 | E10: 13548 | F10: =(E10-D10)/D10 -> 0.25496735 | G10: CNG_Dispenserleri
A11: 46023 | C11: Yük TAS'tan Mak. Kap. 2.000-30.000 kg Arası | D11: 5397.75 | E11: 6774 | F11: =(E11-D11)/D11 -> 0.25496735 | G11: Su_Dışındaki_Sıvılar_İçin_Ölçme_Sistemleri
A12: 46418 | C12: Mak. Kap. 30.001 kg ve Üzeri-(Periyodik, Stok) | D12: 11515 | E12: 14451 | F12: =(E12-D12)/D12 -> 0.25497178 | G12: Hız_İhlal_Tespit_Donanımları
C13: Mak. Kap. 30.001 kg ve Üzeri-(TAS) | D13: 17272.5 | E13: 21676.5 | F13: =(E13-D13)/D13 -> 0.25497178
C14: Yük TAS'tan Mak. Kap. 30.001 kg ve Üzeri | D14: 8636.25 | E14: 10838.25 | F14: =(E14-D14)/D14 -> 0.25497178
B16: Tanker Sayaçları | C16: Tanker Sayaçları-(Periyodik, Stok) | D16: 1080 | E16: 1356 | F16: =(E16-D16)/D16 -> 0.25555556
C17: Tanker Sayaçları-(TAS) | D17: 1620 | E17: 2034 | F17: =(E17-D17)/D17 -> 0.25555556
B19: Su Dışındaki Diğer Sıvılar için Ölçme Sistemleri | C19: (Rafineri veya Gemide Kullanılan) Mak. Akış Hızı 131 L/dk-101 kg/dk Üzeri-(Periyodik, Stok) | D19: 10795 | E19: 13547 | F19: =(E19-D19)/D19 -> 0.25493284
C20: (Rafineri veya Gemide Kullanılan) Mak. Akış Hızı 131 L/dk-101 kg/dk Üzeri-(TAS) | D20: 16192.5 | E20: 20320.5 | F20: =(E20-D20)/D20 -> 0.25493284
C21: Mak. Akış Hızı 751 L/dk-551 kg/dk Üzeri-(Periyodik, Stok) | D21: 1541 | E21: 1934 | F21: =(E21-D21)/D21 -> 0.2550292
C22: Mak. Akış Hızı 751 L/dk-551 kg/dk Üzeri-(TAS) | D22: 2311.5 | E22: 2901 | F22: =(E22-D22)/D22 -> 0.2550292
C23: Mak. Akış Hızı 131-750 L/dk 101-550 kg/dk Arası-(Periyodik, Stok) | D23: 1080 | E23: 1356 | F23: =(E23-D23)/D23 -> 0.25555556
C24: Mak. Akış Hızı 131-750 L/dk 101-550 kg/dk Arası-(TAS) | D24: 1620 | E24: 2034 | F24: =(E24-D24)/D24 -> 0.25555556
C25: Mak. Akış Hızı 130 L/dk-100 kg/dk Kadar-(Periyodik, Stok) | D25: 720 | E25: 904 | F25: =(E25-D25)/D25 -> 0.25555556
C26: Mak. Akış Hızı 130 L/dk-100 kg/dk Kadar-(TAS) | D26: 1080 | E26: 1356 | F26: =(E26-D26)/D26 -> 0.25555556
B28: Akaryakıt Hacim Ölçek Kapları | C28: Hacmi 50 Litreye Kadar Olanlar (50 Litre Dahil) | D28: 72 | E28: 91 | F28: =(E28-D28)/D28 -> 0.26388889
C29: Hacmi 50 Litreden Fazla Olanlar | D29: 216 | E29: 272 | F29: =(E29-D29)/D29 -> 0.25925926
B31: Aks Kantarları | C31: (Periyodik, Stok) | D31: 7197 | E31: 9032 | F31: =(E31-D31)/D31 -> 0.25496735
C32: (TAS) (Yük TSE'den) | D32: 10795.5 | E32: 13548 | F32: =(E32-D32)/D32 -> 0.25496735
C33: (TAS) (Yük TAS'tan) | D33: 5397.75 | E33: 6774 | F33: =(E33-D33)/D33 -> 0.25496735
B35: Demiryolu Yük ve Sarnıçlı Vagonları | C35: Demiryolu Yük ve Sarnıçlı Vagonları | D35: 1440 | E35: 1808 | F35: =(E35-D35)/D35 -> 0.25555556
B37: Lastik Hava Basınçölçerler | C37: Lastik Hava Basınçölçerler | D37: 139 | E37: 175 | F37: =(E37-D37)/D37 -> 0.25899281
B39: Sıkıştırılmış Doğal Gaz (CNG) Ölçme Sistemleri | C39: CNG Dispenserleri-(Periyodik, Stok) | D39: 1080 | E39: 1356 | F39: =(E39-D39)/D39 -> 0.25555556
C40: CNG Dispenserleri-(TAS) | D40: 1620 | E40: 2034 | F40: =(E40-D40)/D40 -> 0.25555556
B42: Hız İhlal Tespit Donanımı | C42: Hız İhlal Tespit Donanımı(Mobil) | D42: 8023 | E42: 10069 | F42: =(E42-D42)/D42 -> 0.25501683
C43: Hız İhlal Tespit Donanımı(Sabit) | D43: 8023 | E43: 10069 | F43: =(E43-D43)/D43 -> 0.25501683
C44: Hız İhlal Tespit Donanımı(Ortalama-Donanım Muayenesi) | D44: 3023 | E44: 3794 | F44: =(E44-D44)/D44 -> 0.25504466
C45: Hız İhlal Tespit Donanımı(Ortalama-Genel Muayene) | D45: 8023 | E45: 10069 | F45: =(E45-D45)/D45 -> 0.25501683
B47: Kütle Ölçüleri | C47: Kütle Setleri | D47: 720 | E47: 904 | F47: =(E47-D47)/D47 -> 0.25555556
C48: M1 Sınıfı- 50 kg Kadar Olanlar (50 kg Dâhil) | D48: 72 | E48: 91 | F48: =(E48-D48)/D48 -> 0.26388889
C49: M1 Sınıfı- 50 kg Üstü | D49: 149 | E49: 187 | F49: =(E49-D49)/D49 -> 0.25503356
...
